Workbook

Sheet IC Summary
A1: Investment Committee Summary
A2: Generated from deterministic Python calculations and final reviewed AI analyses.
A4: TRANSACTION
A5: Deal | B5: ='Assumptions'!$B$7
A6: Acquirer | B6: ='Assumptions'!$B$12
A7: Target | B7: ='Assumptions'!$B$22
A8: Offer enterprise value (USD millions) | B8: ='Assumptions'!$B$49
A9: Offer equity value (USD millions) | B9: ='Transaction Structure'!$B$9
A10: Cash % | B10: ='Transaction Structure'!$B$12
A11: Stock % | B11: ='Transaction Structure'!$B$13
A12: IC review status | B12: approved
A13: Review rounds used | B13: 1
A15: VALUATION SNAPSHOT (USD millions, enterprise value)
A16: Comparable Companies EV | B16: ='Valuation'!$B$22
A17: Precedent Transactions EV | B17: ='Valuation'!$B$27
A18: DCF EV | B18: ='Valuation'!$B$46
A19: Valuation low | B19: ='Valuation'!$B$9
A20: Valuation high | B20: ='Valuation'!$B$10
A21: Offer EV | B21: ='Valuation'!$B$13
A23: SYNERGY SNAPSHOT (USD millions)
A24: PV of synergies | B24: ='Synergies'!$B$16
A25: Integration cost | B25: ='Synergies'!$B$17
A26: Net synergy value | B26: ='Synergies'!$B$18 | C26: Based on unvalidated synergy assumptions.
A28: TRANSACTION SNAPSHOT
A29: Cash consideration (USD millions) | B29: ='Transaction Structure'!$B$14 | C29: Debt funded under the model convention; not a confirmed plan.
A30: Stock consideration (USD millions) | B30: ='Transaction Structure'!$B$15
A31: New shares issued (millions) | B31: ='Transaction Structure'!$B$30
A32: Seller ownership | B32: ='Transaction Structure'!$B$32
A33: EPS result — excluding synergies | B33: ='Accretion Dilution'!$B$17
A34: EPS result — including run-rate synergies | B34: ='Accretion Dilution'!$B$33 | C34: Model scenario only; not the expected outcome.
A36: IC CONCLUSION
A37: Decision deferred pending additional information
A39: KEY UNRESOLVED ITEMS (FINAL IC REVIEW)
A40: • Product, technology, capability, and customer disclosures for EPAM Systems, Inc. are absent from DEAL DATA.
A41: • Multi-period financial statements, quality of earnings reports, capex schedules, tax filings, and working capital details for the target are absent from DEAL DATA.
A42: • Market size, growth rates, competitive landscape, and pricing power data are absent from DEAL DATA.
A43: • Material contracts, change-of-control clauses, litigation records, regulatory compliance filings, IP portfolios, privacy policies, and employee census data are absent from DEAL DATA.
A44: • Organizational charts, IT infrastructure inventories, cybersecurity audit reports, vendor contracts, and real estate lease agreements are absent from DEAL DATA.
A45: • Committed financing term sheets, definitive debt financing agreements, refinancing terms for target existing debt, rollover equity terms, and purchase-price adjustment mechanisms are absent from DEAL DATA.

Sheet Assumptions
A1: Assumptions — Deal Inputs
A2: Generated from deterministic Python calculations and final reviewed AI analyses.
A4: Blue font = supplied input. Yellow fill = unverified assumption requiring validation. All monetary values in USD millions.
A6: DEAL OVERVIEW
A7: Deal name | B7: Hypothetical: Accenture plc acquiring EPAM Systems, Inc.
A8: Currency | B8: USD
A9: Units | B9: millions
A11: ACQUIRER FINANCIALS
A12: Acquirer | B12: Accenture plc
A13: Revenue (USD millions) | B13: 69672.977
A14: EBITDA (USD millions) | B14: 11594.049
A15: Net income (USD millions) | B15: 7678.433
A16: Cash (USD millions) | B16: 10165.245
A17: Debt (USD millions) | B17: 5142.265
A18: Acquirer share basis (millions shares) | B18: 612.21345 | C18: Weighted-average basic shares (modelling proxy)
A19: Share price (USD per share) | B19: 198.9
A21: TARGET FINANCIALS
A22: Target | B22: EPAM Systems, Inc.
A23: Revenue (USD millions) | B23: 5457.056
A24: EBITDA (USD millions) | B24: 644.814
A25: Net income (USD millions) | B25: 377.678
A26: Free cash flow (USD millions) | B26: 612.691
A27: Cash (USD millions) | B27: 789.397
A28: Debt (USD millions) | B28: 25
A30: MARKET VALUATION INPUTS
A31: Comparable EV / EBITDA (x) | B31: 8.2
A32: Precedent EV / EBITDA (x) | B32: 12.3
A34: DCF ASSUMPTIONS
A35: Forecast years | B35: 5
A36: FCF growth rate | B36: 0.08
A37: WACC | B37: 0.105
A38: Terminal growth rate | B38: 0.025
A40: SYNERGY ASSUMPTIONS (UNVALIDATED)
A41: Annual cost synergy (USD millions) | B41: 250
A42: Annual revenue synergy EBITDA (USD millions) | B42: 75
A43: Realization years | B43: 5
A44: Synergy tax rate | B44: 0.253
A45: Synergy discount rate | B45: 0.105
A46: Integration cost (USD millions) | B46: 300
A48: TRANSACTION ASSUMPTIONS
...

Sheet Valuation
A1: Valuation Analysis
A2: Generated from deterministic Python calculations and final reviewed AI analyses.
A4: VALUATION SUMMARY
A5: Method | B5: Enterprise value (USD millions) | C5: Offer EV vs method
A6: Comparable Companies | B6: =$B$22 | C6: above
A7: Precedent Transactions | B7: =$B$27 | C7: below
A8: Discounted Cash Flow | B8: =$B$46 | C8: below
A9: Low | B9: =MIN(B6:B8)
A10: High | B10: =MAX(B6:B8)
A11: Midpoint | B11: =(B9+B10)/2
A12: Average | B12: =AVERAGE(B6:B8)
A13: Offer Enterprise Value | B13: ='Assumptions'!$B$49 | C13: Offer vs range: within
A14: Low method: Comparable Companies; high method: Discounted Cash Flow. Relationship labels are deterministic Python outputs; no premium or discount is calculated.
A19: COMPARABLE COMPANIES
A20: Target EBITDA (USD millions) | B20: ='Assumptions'!$B$24
A21: Comparable EV / EBITDA (x) | B21: ='Assumptions'!$B$31
A22: Implied Enterprise value (USD millions) | B22: =B20*B21
A24: PRECEDENT TRANSACTIONS
A25: Target EBITDA (USD millions) | B25: ='Assumptions'!$B$24
A26: Precedent EV / EBITDA (x) | B26: ='Assumptions'!$B$32
A27: Implied Enterprise value (USD millions) | B27: =B25*B26
A29: DISCOUNTED CASH FLOW
A30: Base free cash flow (USD millions) | B30: ='Assumptions'!$B$26
A31: FCF growth rate | B31: ='Assumptions'!$B$36
A32: WACC | B32: ='Assumptions'!$B$37
A33: Terminal growth rate | B33: ='Assumptions'!$B$38
A34: Forecast years | B34: ='Assumptions'!$B$35
A36: Year | B36: FCF (USD millions) | C36: Discount factor | D36: Discounted FCF (USD millions)
A37: 1 | B37: =B30*(1+B31)^A37 | C37: =1/(1+B32)^A37 | D37: =B37*C37
A38: 2 | B38: =B30*(1+B31)^A38 | C38: =1/(1+B32)^A38 | D38: =B38*C38
A39: 3 | B39: =B30*(1+B31)^A39 | C39: =1/(1+B32)^A39 | D39: =B39*C39
A40: 4 | B40: =B30*(1+B31)^A40 | C40: =1/(1+B32)^A40 | D40: =B40*C40
A41: 5 | B41: =B30*(1+B31)^A41 | C41: =1/(1+B32)^A41 | D41: =B41*C41
A43: PV of forecast FCF (USD millions) | B43: =SUM(D37:D41)
A44: Terminal value (USD millions) | B44: =B41*(1+B33)/(B32-B33)
A45: Discounted terminal value (USD millions) | B45: =B44*C41
A46: DCF Enterprise value (USD millions) | B46: =B43+B45
A47: Terminal value share of EV | B47: =B45/B46
A49: CHART DATA — ENTERPRISE VALUE COMPARISON
A50: Comparable Companies | B50: =$B$22
...

Sheet Synergies
A1: Synergy Analysis
A2: Generated from deterministic Python calculations and final reviewed AI analyses.
A4: SYNERGY ASSUMPTIONS (UNVALIDATED — LINKED TO ASSUMPTIONS)
A5: Annual cost synergy (USD millions) | B5: ='Assumptions'!$B$41
A6: Annual revenue synergy EBITDA (USD millions) | B6: ='Assumptions'!$B$42
A7: Realization years | B7: ='Assumptions'!$B$43
A8: Tax rate | B8: ='Assumptions'!$B$44
A9: Discount rate | B9: ='Assumptions'!$B$45
A11: SYNERGY VALUATION
A12: Annual cost synergy (USD millions) | B12: =B5
A13: Annual revenue synergy EBITDA (USD millions) | B13: =B6
A14: Annual pre-tax synergies (USD millions) | B14: =B5+B6
A15: Annual after-tax synergies (USD millions) | B15: =B14*(1-B8)
A16: PV of synergies (USD millions) | B16: =SUM(D22:D26)
A17: Integration cost (at close) (USD millions) | B17: ='Assumptions'!$B$46
A18: Net synergy value (USD millions) | B18: =B16-B17 | C18: Status: positive
A20: DISCOUNTED SYNERGY SCHEDULE
A21: Year | B21: After-tax synergy (USD millions) | C21: Discount factor | D21: Discounted synergy (USD millions)
A22: 1 | B22: =B15 | C22: =1/(1+B9)^A22 | D22: =B22*C22
A23: 2 | B23: =B15 | C23: =1/(1+B9)^A23 | D23: =B23*C23
A24: 3 | B24: =B15 | C24: =1/(1+B9)^A24 | D24: =B24*C24
A25: 4 | B25: =B15 | C25: =1/(1+B9)^A25 | D25: =B25*C25
A26: 5 | B26: =B15 | C26: =1/(1+B9)^A26 | D26: =B26*C26
A28: MODELLING CONVENTIONS
A29: • Full run-rate synergies from year one (no ramp-up).
A30: • Finite realization period; no terminal synergy value.
A31: • Integration cost is incurred at close, undiscounted and not tax-deductible.
A32: • Synergy assumptions are unvalidated DEAL DATA assumptions.
A33: • Integration cost vs PV of synergies (deterministic label): below.

Sheet Transaction Structure
A1: Transaction Structure
A2: Generated from deterministic Python calculations and final reviewed AI analyses.
A4: PURCHASE PRICE
A5: Offer enterprise value (USD millions) | B5: ='Assumptions'!$B$49
A6: Target debt (USD millions) | B6: ='Assumptions'!$B$28
A7: Target cash (USD millions) | B7: ='Assumptions'!$B$27
A8: Target net debt (USD millions) | B8: =B6-B7
A9: Offer equity value (USD millions) | B9: =B5-B8
A11: CONSIDERATION
A12: Cash % | B12: ='Assumptions'!$B$50
A13: Stock % | B13: ='Assumptions'!$B$51
A14: Cash consideration (USD millions) | B14: =B9*B12
A15: Stock consideration (USD millions) | B15: =B9*B13
A17: FINANCING MODEL CONVENTION
A18: The model assumes the cash portion of the equity purchase price is funded entirely with new debt at the supplied new-debt interest rate.
A19: This is a modelling convention, NOT a confirmed financing plan.
A20: New debt under model convention (USD millions) | B20: =B14
A21: New debt interest rate | B21: ='Assumptions'!$B$52
A22: Pre-tax interest expense (USD millions) | B22: =B20*B21
A23: Tax rate | B23: ='Assumptions'!$B$53
A24: After-tax interest expense (USD millions) | B24: =B22*(1-B23)
A25: Not modelled: leverage, debt capacity, covenant headroom, or credit-rating impact.
A27: SHARE ISSUANCE / OWNERSHIP
A28: Acquirer share price (USD per share) | B28: ='Assumptions'!$B$19
A29: Existing shares (millions) | B29: ='Assumptions'!$B$18
A30: New shares issued (millions) | B30: =B15/B28
A31: Pro forma shares (millions) | B31: =B29+B30
A32: Seller ownership | B32: =B30/B31
A33: Existing acquirer holder ownership | B33: =1-B32

Sheet Accretion Dilution
A1: Accretion / Dilution
A2: Generated from deterministic Python calculations and final reviewed AI analyses.
A4: CASE A — EXCLUDING SYNERGIES
A5: Acquirer standalone net income (USD millions) | B5: ='Assumptions'!$B$15
A6: Target net income (USD millions) | B6: ='Assumptions'!$B$25
A7: After-tax interest expense (USD millions) | B7: ='Transaction Structure'!$B$24
A8: Synergy contribution (USD millions) | B8: 0
A9: Pro forma net income (USD millions) | B9: =B5+B6-B7+B8
A10: Existing shares (millions) | B10: ='Assumptions'!$B$18
A11: New shares issued (millions) | B11: ='Transaction Structure'!$B$30
A12: Pro forma shares (millions) | B12: =B10+B11
A13: Standalone EPS (USD per share) | B13: =B5/B10
A14: Pro forma EPS (USD per share) | B14: =B9/B12
A15: EPS change (USD per share) | B15: =B14-B13
A16: EPS change % | B16: =IF(B13=0,"n/a",B15/ABS(B13))
A17: Result | B17: =IF(ABS(B15)<1E-12,"Neutral",IF(B15>0,"Accretive","Dilutive"))
A19: CASE B — INCLUDING FULL RUN-RATE SYNERGIES
A20: Synergy-inclusive accretion assumes full supplied run-rate synergies and should not be interpreted as the expected outcome.
A21: Acquirer standalone net income (USD millions) | B21: ='Assumptions'!$B$15
A22: Target net income (USD millions) | B22: ='Assumptions'!$B$25
A23: After-tax interest expense (USD millions) | B23: ='Transaction Structure'!$B$24
A24: Synergy contribution (after tax) (USD millions) | B24: ='Synergies'!$B$15
A25: Pro forma net income (USD millions) | B25: =B21+B22-B23+B24
A26: Existing shares (millions) | B26: ='Assumptions'!$B$18
A27: New shares issued (millions) | B27: ='Transaction Structure'!$B$30
A28: Pro forma shares (millions) | B28: =B26+B27
A29: Standalone EPS (USD per share) | B29: =B21/B26
A30: Pro forma EPS (USD per share) | B30: =B25/B28
A31: EPS change (USD per share) | B31: =B30-B29
A32: EPS change % | B32: =IF(B29=0,"n/a",B31/ABS(B29))
A33: Result | B33: =IF(ABS(B31)<1E-12,"Neutral",IF(B31>0,"Accretive","Dilutive"))
A35: Both cases are single-year, run-rate EPS views from the deterministic accretion_dilution model. Neither case is a base, expected, or most likely case.

Sheet Due Diligence
A1: Due Diligence — Final Reviewed Outputs
A2: Generated from deterministic Python calculations and final reviewed AI analyses.
A4: FINANCIAL DUE DILIGENCE
A5: Current version: 1 — run kind: initial (initial analysis)
A6: Financial Due Diligence
A8: Observed Financial Evidence
A9: - DEAL DATA reports target revenue of 5457.056, EBITDA of 644.814, net_income of 377.678, free_cash_flow of 612.691, cash of 789.397, and debt of 25.0.
A10: - DETERMINISTIC CALCULATIONS reports target net debt of -764.397.
A11: - DEAL DATA reports acquirer revenue of 69672.977, EBITDA of 11594.049, net_income of 7678.433, cash of 10165.245, debt of 5142.265, an acquirer share basis of 612.213453 (defined as weighted-average basic shares used as a modelling proxy), and a share price of 198.9.
A12: - MARKET DATA includes a comparable_ev_ebitda_multiple of 8.2 and a precedent_ev_ebitda_multiple of 12.3.
A13: - DCF ASSUMPTIONS includes forecast_years of 5, fcf_growth_rate of 0.08, wacc of 0.105, and terminal_growth_rate of 0.025.
A14: - SYNERGY ASSUMPTIONS includes annual_cost_synergy of 250.0, annual_revenue_synergy_ebitda of 75.0, realization_years of 5, tax_rate of 0.253, discount_rate of 0.105, and integration_cost of 300.0.
... A163: - Recommended diligence action: review the operational feasibility, execution timeline, and budgetary adequacy underlying the integration_cost of 300.0 and the realization_years of 5.

Sheet Risk Summary
A1: Risk Summary
A2: Generated from deterministic Python calculations and final reviewed AI analyses.
A4: RISK ANALYST — FINAL REVIEWED OUTPUT
A5: Current version: 1 — run kind: initial (initial analysis)
A6: Deal Risk Assessment
A8: Evidence-Backed Risks
A9: - EVIDENCE-BACKED RISK: The valuation methods produce a wide enterprise value dispersion, ranging from 5287.4748 under the Comparable Companies method to 9863.0608 under the Discounted Cash Flow method, with the offer_enterprise_value of 6300.0 sitting above the Comparable Companies method but below the Precedent Transactions method (7931.2122) and the Discounted Cash Flow method (9863.0608), as reported in DETERMINISTIC CALCULATIONS.
A10: - EVIDENCE-BACKED RISK: The financing structure modelled in DETERMINISTIC CALCULATIONS introduces significant debt obligations, with new_debt_under_financing_convention of 4945.0779 generating an annual_pre_tax_interest_expense of 271.9793 and an annual_after_tax_interest_expense of 203.1685 at the new_debt_interest_rate of 0.055.
A12: Unverified Assumptions
A13: - UNVERIFIED ASSUMPTION: `comparable_ev_ebitda_multiple` of 8.2 and `precedent_ev_ebitda_multiple` of 12.3, sourced from market_data (DEAL DATA ASSUMPTIONS), which drive the Comparable Companies and Precedent Transactions valuation methods.
A14: - UNVERIFIED ASSUMPTION: `fcf_growth_rate` of 0.08, `wacc` of 0.105, `terminal_growth_rate` of 0.025, and `forecast_years` of 5, sourced from dcf_assumptions (DEAL DATA ASSUMPTIONS), which drive the Discounted Cash Flow enterprise value of 9863.0608.
A15: - UNVERIFIED ASSUMPTION: `annual_cost_synergy` of 250.0, `annual_revenue_synergy_ebitda` of 75.0, `realization_years` of 5, `tax_rate` of 0.253, `discount_rate` of 0.105, and `integration_cost` of 300.0, sourced from synergy_assumptions (DEAL DATA ASSUMPTIONS), which drive the deterministic pv_synergies of 908.6724 and net_synergy_value of 608.6724.
... A75: • Committed financing term sheets, definitive debt financing agreements, refinancing terms for target existing debt, rollover equity terms, and purchase-price adjustment mechanisms are absent from DEAL DATA.

Sheet IC Memo
A1: Investment Committee Memo
A2: Generated from deterministic Python calculations and final reviewed AI analyses.
A4: IC CONCLUSION
A5: Decision deferred pending additional information
A7: Investment Committee Memorandum
A9: Transaction Overview
A10: This memorandum evaluates the proposed transaction in which Accenture plc ("acquirer") acquires EPAM Systems, Inc. ("target"). DEAL DATA reports that Accenture plc has revenue of 69672.977, EBITDA of 11594.049, net_income of 7678.433, cash of 10165.245, and debt of 5142.265, with an acquirer share basis of 612.213453, defined in DEAL DATA as weighted-average basic shares used as a modelling proxy, and a share price of 198.9. EPAM Systems, Inc. reports revenue of 5457.056, EBITDA of 644.814, net_income of 377.678, free_cash_flow of 612.691, cash of 789.397, and debt of 25.0.
A11: The supplied offer terms consist of an offer_enterprise_value of 6300.0. The consideration structure comprises a cash_percentage of 0.7 and a stock_percentage of 0.3. As noted in DETERMINISTIC CALCULATIONS, debt funding of the cash portion is a modelling convention of the deterministic model, not a confirmed financing plan.
A13: Executive Summary
A14: The deal team has reviewed the supplied DEAL DATA and DETERMINISTIC CALCULATIONS. The strategic rationale remains unassessed due to the absence of product, technology, capability, and customer data in DEAL DATA. Valuation methods produce an enterprise value range from a low of 5287.4748 under the Comparable Companies method to a high of 9863.0608 under the Discounted Cash Flow method, with the offer_enterprise_value of 6300.0 sitting within the range. Synergy assumptions (annual_cost_synergy of 250.0 and annual_revenue_synergy_ebitda of 75.0) yield a deterministic pv_synergies of 908.6724 and a net_synergy_value of 608.6724 after deducting an integration_cost of 300.0, though these synergy assumptions remain unverified. Financial, commercial, legal, and operational due diligence is severely constrained by extensive information gaps, including the complete absence of multi-period financial statements, material contracts, customer concentration data, organizational charts, and committed financing term sheets. Major unresolved issues include unverified synergy assumptions, unconfirmed financing arrangements, and pervasive information gaps across all diligence workstreams.
A16: Strategic Rationale
A17: The Deal Lead and Strategic Fit Analyst observe that DEAL DATA reports revenue of 69672.977 and EBITDA of 11594.049 for Accenture plc, and revenue of 5457.056 and EBITDA of 644.814 for EPAM Systems, Inc. However, DEAL DATA contains no product, technology, capability, customer, geographic, or market-share information for either company. Consequently, a product-led or capability-led strategic rationale, geographic fit, commercial positioning, and buy-versus-build considerations cannot be assessed from the supplied data. These areas represent significant unresolved information gaps.
... A57: Decision deferred pending additional information
